Traceback (most recent call last):
  File "C:\Users\mich0003\AppData\Local\anaconda3\envs\proactive\lib\site-packages\wandb\sdk\wandb_config.py", line 162, in __getattr__
    return self.__getitem__(key)
  File "C:\Users\mich0003\AppData\Local\anaconda3\envs\proactive\lib\site-packages\wandb\sdk\wandb_config.py", line 130, in __getitem__
    return self._items[key]
KeyError: 'data'
The above exception was the direct cause of the following exception:
Traceback (most recent call last):
  File "C:\Users\mich0003\Repos\BachelorPP\proactive\strategies\architecture\wandb\hawkes_training_wandb.py", line 22, in train
    trainloader, testloader, num_types, num_goals = initial_dataloader_preparation(config)
  File "C:\Users\mich0003\Repos\BachelorPP\proactive\data_preparation.py", line 8, in initial_dataloader_preparation
    train_data, num_types, num_goals = _load_data(opt.data + 'train.pkl', 'train')
  File "C:\Users\mich0003\AppData\Local\anaconda3\envs\proactive\lib\site-packages\wandb\sdk\wandb_config.py", line 166, in __getattr__
    ) from ke
AttributeError: <class 'wandb.sdk.wandb_config.Config'> object has no attribute 'data'
Training hawkes transformer...
{}
Loading All Datasets...