{'activation': 'softplus', 'batch_size': 4, 'd_inner': 256, 'd_k': 4, 'd_model': 64, 'd_rnn': 0, 'd_v': 4, 'data': 'data/Breakfast/', 'device': 'cuda', 'dropout': 0.1, 'epoch': 100, 'learning_rate': 0.01, 'n_layer': 4, 'smooth': [0, 0.1]}
Loading All Datasets...
45 9
Traceback (most recent call last):
  File "C:\Users\mich0003\AppData\Local\anaconda3\envs\proactive\lib\site-packages\wandb\sdk\wandb_config.py", line 162, in __getattr__
    return self.__getitem__(key)
  File "C:\Users\mich0003\AppData\Local\anaconda3\envs\proactive\lib\site-packages\wandb\sdk\wandb_config.py", line 130, in __getitem__
    return self._items[key]
KeyError: 'n_layers'
The above exception was the direct cause of the following exception:
Traceback (most recent call last):
  File "C:\Users\mich0003\Repos\BachelorPP\proactive\strategies\architecture\hawkes_training_wandb.py", line 34, in train
    n_layers=config.n_layers,
  File "C:\Users\mich0003\AppData\Local\anaconda3\envs\proactive\lib\site-packages\wandb\sdk\wandb_config.py", line 166, in __getattr__
    ) from ke
AttributeError: <class 'wandb.sdk.wandb_config.Config'> object has no attribute 'n_layers'