Traceback (most recent call last):
  File "C:\Users\mich0003\AppData\Local\anaconda3\envs\proactive\lib\site-packages\wandb\sdk\wandb_config.py", line 162, in __getattr__
    return self.__getitem__(key)
  File "C:\Users\mich0003\AppData\Local\anaconda3\envs\proactive\lib\site-packages\wandb\sdk\wandb_config.py", line 130, in __getitem__
    return self._items[key]
KeyError: 'data'
The above exception was the direct cause of the following exception:
Traceback (most recent call last):
  File "C:\Users\mich0003\Repos\BachelorPP\proactive\strategies\architecture\hawkes_training_wandb.py", line 26, in train
    trainloader, testloader, num_types, num_goals = initial_dataloader_preparation(config)
  File "C:\Users\mich0003\Repos\BachelorPP\proactive\data_preparation.py", line 8, in initial_dataloader_preparation
    train_data, num_types, num_goals = _load_data(opt.data + 'train.pkl', 'train')
  File "C:\Users\mich0003\AppData\Local\anaconda3\envs\proactive\lib\site-packages\wandb\sdk\wandb_config.py", line 166, in __getattr__
    ) from ke
AttributeError: <class 'wandb.sdk.wandb_config.Config'> object has no attribute 'data'
{'activation': 'default', 'batch_size': 4, 'd_inner': 256, 'd_k': 4, 'd_model': 64, 'd_rnn': 0, 'd_v': 4, 'device': 'cuda', 'dropout': 0.1, 'epoch': 100, 'learning_rate': 0.0001, 'n_layer': 4, 'smooth': [0, 0.1]}
Loading All Datasets...